Workbook

Sheet Январь
A1: Анализ продаж торговой фирмы "МУСОР"
A2: Наименова-ние товара | B2: Цена за единицу (у.е.) | D2: Предложе-ние (шт.) | E2: Продажа | H2: Выручка от продаж, у.е. | I2: Остаток на складе
B3: Нал. | C3: Безнал. | E3: Нал. | F3: Безнал. | G3: Всего
A4: Телевизор | B4: 300 | C4: 310 | D4: 20 | E4: 5 | F4: 10 | G4: =E4+F4 -> 15 | H4: =B4*E4+C4*F4 -> 4600 | I4: =D4-G4 -> 5
A5: Кофеварка | B5: 200 | C5: 205 | D5: 25 | E5: 5 | F5: 7 | G5: =E5+F5 -> 12 | H5: =B5*E5+C5*F5 -> 2435 | I5: =D5-G5 -> 13
A6: Музыкаль-ный центр | B6: 275 | C6: 280 | D6: 30 | E6: 9 | F6: 7 | G6: =E6+F6 -> 16 | H6: =B6*E6+C6*F6 -> 4435 | I6: =D6-G6 -> 14
A7: Видеокамера | B7: 415 | C7: 430 | D7: 10 | E7: 2 | F7: 8 | G7: =E7+F7 -> 10 | H7: =B7*E7+C7*F7 -> 4270 | I7: =D7-G7 -> 0
A8: Фотоаппарат | B8: 50 | C8: 51 | D8: 100 | E8: 57 | F8: 34 | G8: =E8+F8 -> 91 | H8: =B8*E8+C8*F8 -> 4584 | I8: =D8-G8 -> 9

Sheet Февраль
A1: Анализ продаж торговой фирмы "МУСОР"
A2: Наименова-ние товара | B2: Цена за единицу (у.е.) | D2: Предложе-ние (шт.) | E2: Продажа | H2: Выручка от продаж, у.е. | I2: Остаток на складе
B3: Нал. | C3: Безнал. | E3: Нал. | F3: Безнал. | G3: Всего
A4: Телевизор | B4: 300 | C4: 300 | D4: 20 | E4: 10 | F4: 8 | G4: =E4+F4 -> 18 | H4: =B4*E4+C4*F4 -> 5400 | I4: =D4-G4 -> 2
A5: Кофеварка | B5: 201 | C5: 105 | D5: 21 | E5: 5 | F5: 7 | G5: =E5+F5 -> 12 | H5: =B5*E5+C5*F5 -> 1740 | I5: =D5-G5 -> 9
A6: Музыкаль-ный центр | B6: 275 | C6: 180 | D6: 302 | E6: 9 | F6: 7 | G6: =E6+F6 -> 16 | H6: =B6*E6+C6*F6 -> 3735 | I6: =D6-G6 -> 286
A7: Видеокамера | B7: 315 | C7: 330 | D7: 50 | E7: 2 | F7: 8 | G7: =E7+F7 -> 10 | H7: =B7*E7+C7*F7 -> 3270 | I7: =D7-G7 -> 40
A8: Фотоаппарат | B8: 50 | C8: 51 | D8: 100 | E8: 57 | F8: 34 | G8: =E8+F8 -> 91 | H8: =B8*E8+C8*F8 -> 4584 | I8: =D8-G8 -> 9

Sheet Март
A1: Анализ продаж торговой фирмы "МУСОР"
A2: Наименова-ние товара | B2: Цена за единицу (у.е.) | D2: Предложе-ние (шт.) | E2: Продажа | H2: Выручка от продаж, у.е. | I2: Остаток на складе
B3: Нал. | C3: Безнал. | E3: Нал. | F3: Безнал. | G3: Всего
A4: Телевизор | B4: 303 | C4: 310 | D4: 25 | E4: 5 | F4: 10 | G4: =E4+F4 -> 15 | H4: =B4*E4+C4*F4 -> 4615 | I4: =D4-G4 -> 10
A5: Кофеварка | B5: 201 | C5: 205 | D5: 23 | E5: 5 | F5: 7 | G5: =E5+F5 -> 12 | H5: =B5*E5+C5*F5 -> 2440 | I5: =D5-G5 -> 11
A6: Музыкаль-ный центр | B6: 175 | C6: 280 | D6: 35 | E6: 9 | F6: 7 | G6: =E6+F6 -> 16 | H6: =B6*E6+C6*F6 -> 3535 | I6: =D6-G6 -> 19
A7: Видеокамера | B7: 412 | C7: 430 | D7: 10 | E7: 2 | F7: 8 | G7: =E7+F7 -> 10 | H7: =B7*E7+C7*F7 -> 4264 | I7: =D7-G7 -> 0
A8: Фотоаппарат | B8: 54 | C8: 51 | D8: 100 | E8: 57 | F8: 34 | G8: =E8+F8 -> 91 | H8: =B8*E8+C8*F8 -> 4812 | I8: =D8-G8 -> 9

Sheet Итог
A1: Сводные показатели за 1 квартал
A2: Наименование товара | B2: Продано (шт.) | C2: Выручка за 1 квартал, у.е.
B3: =Март!$G$4 -> 15
B4: =Февраль!$G$4 -> 18
B5: =Январь!$G$4 -> 15
C6: =Март!$H$4 -> 4615
C7: =Февраль!$H$4 -> 5400
C8: =Январь!$H$4 -> 4600
C9: =Март!$H$4 -> 4615
C10: =Февраль!$H$4 -> 5400
C11: =Январь!$H$4 -> 4600
C15: =Март!$H$4 -> 4615
C16: =Февраль!$H$4 -> 5400
C17: =Январь!$H$4 -> 4600
C18: =Март!$H$4 -> 4615
C19: =Февраль!$H$4 -> 5400
C20: =Январь!$H$4 -> 4600
C21: =SUM(C18:C20) -> 14615
C22: =Март!$H$5 -> 2440
C23: =Февраль!$H$5 -> 1740
C24: =Январь!$H$5 -> 2435
C25: =SUM(C22:C24) -> 6615
C26: =Март!$H$6 -> 3535
C27: =Февраль!$H$6 -> 3735
C28: =Январь!$H$6 -> 4435
C29: =SUM(C26:C28) -> 11705
C30: =Март!$H$7 -> 4264
C31: =Февраль!$H$7 -> 3270
C32: =Январь!$H$7 -> 4270
A42: Телевизор | B42: =SUM(B3:B5) -> 48 | C42: =SUM(C30:C32) -> 11804
C70: =SUM(C31:C42) -> 19344
C74: =SUM(C32:C70) -> 35418
C78: =SUM(C42:C74) -> 66566
C82: =SUM(C70:C78) -> 121328
C83: =SUM(C74:C82) -> 223312
C84: =SUM(C78:C83) -> 411206
C85: =SUM(C82:C84) -> 755846
C86: =SUM(C83:C85) -> 1390364
C87: =SUM(C84:C86) -> 2557416
C88: =SUM(C85:C87) -> 4703626
...
